<?xml version="1.0"?>
<robot name="ceterio_c_100">

  <!-- Base Link -->
  <link name="base_link">
    <inertial>
      <mass value="30.0"/>
      <inertia ixx="0.1" ixy="0.0" ixz="0.0" iyy="0.1" iyz="0.0" izz="0.1"/>
    </inertial>
    <visual>
      <geometry>
        <box size="0.72175 0.52175 0.11"/>
      </geometry>
    </visual>
    <collision>
      <geometry>
        <box size="0.72175 0.52175 0.2"/>
      </geometry>
    </collision>
  </link>

  <!-- Left Wheel -->
  <link name="left_wheel">
    <inertial>
      <mass value="1.0"/>
      <inertia ixx="0.01" ixy="0.0" ixz="0.0" iyy="0.01" iyz="0.0" izz="0.01"/>
    </inertial>
    <visual>
      <geometry>
        <cylinder radius="0.037" length="0.028"/>
      </geometry>
    </visual>
    <collision>
      <geometry>
        <cylinder radius="0.037" length="0.028"/>
      </geometry>
    </collision>
  </link>
  <joint name="left_wheel_joint" type="continuous">
    <parent link="base_link"/>
    <child link="left_wheel"/>
    <axis xyz="0 1 0"/>
    <origin xyz="0 0.1743 0.037" rpy="0 -1.5708 0"/>
  </joint>

  <!-- Right Wheel -->
  <link name="right_wheel">
    <inertial>
      <mass value="1.0"/>
      <inertia ixx="0.01" ixy="0.0" ixz="0.0" iyy="0.01" iyz="0.0" izz="0.01"/>
    </inertial>
    <visual>
      <geometry>
        <cylinder radius="0.037" length="0.028"/>
      </geometry>
    </visual>
    <collision>
      <geometry>
        <cylinder radius="0.037" length="0.028"/>
      </geometry>
    </collision>
  </link>
  <joint name="right_wheel_joint" type="continuous">
    <parent link="base_link"/>
    <child link="right_wheel"/>
    <axis xyz="0 1 0"/>
    <origin xyz="0 -0.1743 0.037" rpy="0 -1.5708 0"/>
  </joint>

  <!-- Front LiDAR -->
  <link name="front_lidar">
    <inertial>
      <mass value="0.5"/>
      <inertia ixx="0.01" ixy="0.0" ixz="0.0" iyy="0.01" iyz="0.0" izz="0.01"/>
    </inertial>
    <visual>
      <geometry>
        <cylinder radius="0.04337" length="0.035"/>
      </geometry>
    </visual>
    <collision>
      <geometry>
        <cylinder radius="0.04337" length="0.035"/>
      </geometry>
    </collision>
  </link>
  <joint name="front_lidar_joint" type="fixed">
    <parent link="base_link"/>
    <child link="front_lidar"/>
    <origin xyz="0.198 0 0.13" rpy="0 0 0"/>
  </joint>

  <!-- Rear LiDAR -->
  <link name="rear_lidar">
    <inertial>
      <mass value="0.5"/>
      <inertia ixx="0.01" ixy="0.0" ixz="0.0" iyy="0.01" iyz="0.0" izz="0.01"/>
    </inertial>
    <visual>
      <geometry>
        <cylinder radius="0.04337" length="0.035"/>
      </geometry>
    </visual>
    <collision>
      <geometry>
        <cylinder radius="0.04337" length="0.035"/>
      </geometry>
    </collision>
  </link>
  <joint name="rear_lidar_joint" type="fixed">
    <parent link="base_link"/>
    <child link="rear_lidar"/>
    <origin xyz="-0.198 0 0.13" rpy="0 0 0"/>
  </joint>

</robot>
